Workbook

Sheet How to Use
A1: TILKIT Weather Indicator Log — Master Template v4 (reviewed and extended, 19 October 2026)
A3: What this workbook does | B3: One row per indicator, per site, per season, in the Indicator Log. The Seasonal Tercile Tally turns the eligible rows into a simple and a weighted community forecast (above/ normal/ below). After each season, scoring each indicator Hit/ Miss/ False Start feeds its hit rate into the next season's weights.
A5: Where to type
A6: Indicator Log, rows 12–500 | B6: All white cells in columns A to BK and BU to BZ, and the white v4 columns CI–DP (except the grey auto columns). Columns with dropdowns must use a dropdown value.
A7: Auto columns — do not type | B7: AW–AY (onset/ cessation/ distribution checks), BL–BT (calibration metrics), CA–CC (weights, stability), CD–CH (data checks, tally feed), and the v4 auto columns CJ, CM, CP, CS–CV, DH, DI, DK, DQ–DT.
A8: Seasonal Tercile Tally, yellow cells | B8: B3 site, B4 season (type exactly as in the log), B5 = 1 (Yes) or 0 (No) for the optional global prior.
A9: Rows 5–11 of the log | B9: Category guide rows with photo instructions — not data. Data starts at row 12.
A11: Fields the tally needs (record for every indicator)
A12: AH Unique Indicator ID | B12: From the Indicator Code Legend + running number; identical across seasons and sites. Rows without an ID are not tallied.
A13: AI Community/ Site and AM Season/ Year | B13: Exactly as typed in Tally B3/B4, e.g. "Mutirithia" and "OND 2026". Same spelling every time.
A14: N Sighted this season | B14: Y or N. Record date and place in O.
A15: AC Confirmed and AD Approved | B15: 1 = Yes, 0 = No from the dropdown. Names go in the Observed-by or Notes columns.
A16: AP Validation status | B16: Dropdown. "Contested" rows are excluded.
A17: U Tercile from this indicator | B17: 3 above, 2 normal, 1 below, 0 no prediction yet (0 is not tallied).
A18: M Current reliability | B18: 3 High (green), 2 Medium (amber), 1 Low (red), 0 Not sure (grey). 0 = counted in the simple tally but carries no weight.
A19: P–Q Onset, R–S Cessation, T Distribution | B19: Predicted onset and cessation windows as dates (earliest, latest) and distribution 3 Good, 2 Fair, 1 Poor, 0 Not sure. Summarised on the Tally tab (rows 37–50) for comparison with the KMSA outlook.
A20: V Decision relevance | B20: 3 High, 2 Medium, 1 Low, 0 Not sure. Multiplies the weight; blank or 0 counts as 1 and is flagged.
A21: AZ Outcome (after the season) | B21: Hit, Miss or False Start, after comparing P/U with actual onset AS and actual tercile AV. Drives the hit rate from the next season.
A23: How the weights are calculated
A24: 1. Gate | B24: Has ID; sighted = 1; Confirmed = 1; Approved = 1; not Contested; tercile 3/2/1; matches Tally site and season.
A25: 2. Phase | B25: Rating-based until the Indicator ID has 3 scored seasons (Hit/Miss/False Start), then Hit-rate-based.
A26: 3. Base Weight | B26: Rating-based: current reliability (3 High, 2 Medium, 1 Low; 0 Not sure carries no weight). Hit-rate-based: ≥70% = 3, ≥40% = 2, below 40% = 1.
A27: 4. Corroboration cap | B27: Base Weight is capped at 2 while the ID has fewer than 2 records that were Confirmed and Approved (all sites and seasons).
A28: 5. Final Weight | B28: Base Weight × Decision relevance (1–3). Range 0–9.
A29: 6. Optional global prior | B29: If Tally B5 = 1 (Yes), Rating-based indicators are also multiplied by their Prior Multiplier (0.55–1.35). Hit-rate-based indicators never are.
A30: 7. Composites (Protocol Step 5) | B30: Not automated. If several indicators are treated as one vote, note it in BA and reduce the other members' Decision relevance.
A31: Worked example | B31: Frogs croaking at night: current rating 3 (High, green), relevance 3 (High), first season (1 corroboration) → Base Weight capped at 2 → Final Weight 6. Next season, once confirmed and approved again (2 corroborations), Base Weight 3 → Final Weight 9.
A33: Converting data from older forms
A34: Template_0 ("Table 2", plenary form) | B34: Tercile coded the other way round: 1 = above normal, 3 = below normal. Convert 1→3 and 3→1 before entering in U. Its "Forecast (Y=Yes)" column = sighted.
A35: Community forms dated 01.08.2026 and 22.08.2026 | B35: Historical/ new: old forms coded 1 = historical, 2 = new; this log uses J = 3 ancient/ historical, 2 recent but promising, 1 new/ emerging, 0 not sure — convert old 1 → 3 and old 2 → 1. Hit/ Miss was coded Hit = 1, Miss = 0 — enter the words in AZ. Validation status was written inside the "Confirmed" column — split it into AC (1 = Yes, 0 = No) and AP. Year/ Season/ Month/ Week/ Day/ Country/ sub-national levels move into AM, O/ CI, AJ, AK, AL. Sector ratings go in X.
A36: Template__2 ("Verified, Entered and Approved") | B36: Split into Verified (AE), Entered by (AF) and Approved (AD).
A37: Yes/No coding | B37: All Yes/No columns are coded 1 = Yes, 0 = No. Convert Y/N, Yes/No and the old disability coding (1 Yes, 2 No) when copying from older forms.
A38: Category codes (realigned 13 Oct 2026) | B38: Use 01 Biological/ Ecological (01-PLT plant-based, 01-ANI animal-based), 02 Atmospheric/ Physical/ Meteorological, 03 Astronomical/ Astrological/ Celestial, 04 Hydrological/ Water-related, 05 Traditional ritual/ divinatory/ hidden, 06 Sensory/ human body. Convert older IDs by their type letters: AST → 03, ATM → 02, HYD → 04, PLT and ANI → 01, RIT → 05, SEN → 06 (e.g., 03-ANI-FRO-001 or 04-ANI-… → 01-ANI-…; 01-AST-STR-001 → 03-AST-STR-001; 02-HYD-… → 04-HYD-…). The Africa-wide catalogue numbering (03 Hydrological, 04 Biological, 05 Sensory, 06 Ritual) is retired too.
A39: July 2026 Mutirithia log | B39: Re-enter each July sign as its own row with Season/ Year "July 2026" and the same Unique Indicator ID you will use in OND, so its July confirmation counts as corroboration.
A41: Example row (format only — not in the log)
A42: Example | B42: Category 01 Biological/ Ecological (01-ANI) · Type Animals · Indicator "frogs croaking at night near the dam" · Local name Teneru Ituan (Maa) · History 3 (ancient) · Lead time 2 (weeks) · Historical rating 3 · Current rating 3 · Sighted 1 · Where/when "12/10/2026, Mutirithia dam" (and CI = 12/10/2026) · Onset window P 20/10/2026, Q 31/10/2026 · Tercile 3 · Decision relevance 3 · Confirmed 1 · Approved 1 · ID 01-ANI-FRO-001 · Site Mutirithia · Ward Segera · County Laikipia · Country Kenya · Season OND 2026 · Validation status Community/Plenary-endorsed · Expected month CL 10 · KMD/ KMSA tercile DJ 3.
A44: What changed in this version
A45: Weighting | B45: All ratings use one traffic-light scale: 3 High (green), 2 Medium (amber), 1 Low (red), 0 Not sure (grey) — historical and current reliability, decision relevance, sector impact, Base Weight. Decision relevance added and multiplied into the Final Weight; separate Base Weight column for transparency.
A46: Tally | B46: Rebuilt: requires an ID; uses the weight column CG; "Season/ Year" label added; leading tercile and simple-vs-weighted agreement; data-check counts by exclusion reason; optional global prior switch; notes now cite the correct columns.
A47: New log fields | B47: Where/ when sighted; decision relevance; sector impact rating; entered by (data desk); ward; county; country; duplicate check; tally status; prior multiplier; tally weight.
...

Sheet Community Data List
A1: Community Data List — what observers and the community must collect and report for the Seasonal Tercile Tally
A2: One row per sign, per site, per season. Code every Yes/No as 1 = Yes, 0 = No; ratings 3 High, 2 Medium, 1 Low, 0 Not sure; dates as dd/mm/yyyy. Ask about the coming season (OND) only. "Feeds" shows which part of the Tally tab each item drives.
A4: A. For every sign — FGD/ plenary at the start of the season, updated by observers
A5: # | B5: What to report | C5: Column(s) | D5: How to record it | E5: Who reports/ decides | F5: When | G5: Feeds (Tally tab)
A6: 1 | B6: The exact sign seen, in local words (e.g., "frogs croaking at night near the dam") and its local name | C6: D, F | D6: Words | E6: Observer/ FGD | F6: FGD; each new sign | G6: Basis for the Indicator ID
A7: 2 | B7: Kind of sign: plant, animal, atmosphere, sky (sun/ moon/ stars), water, ritual or body | C7: A, B | D7: One of the 7 category lines (01-PLT, 01-ANI, 02-ATM, 03-AST, 04-HYD, 05-RIT, 06-SEN) | E7: Observer/ FGD | F7: FGD | G7: Basis for the Indicator ID
A8: 3 | B8: Has it been seen this season? | C8: N | D8: 1 = Yes, 0 = No | E8: Observer | F8: Each sighting | G8: Gate: only 1 is counted
A9: 4 | B9: ONSET — when will the rains START, according to this sign? | C9: P (earliest), Q (latest) | D9: Two dates, e.g. 20/10/2026 and 31/10/2026 (one date → earliest only) | E9: Observer, agreed by ITK holders | F9: FGD; update when seen | G9: Community onset window (rows 39–40, 43)
A10: 5 | B10: CESSATION — when will the rains END, according to this sign? | C10: R (earliest), S (latest) | D10: Two dates, e.g. 05/01/2027 and 20/01/2027; blank if the sign says nothing about the end | E10: Observer, agreed by ITK holders | F10: FGD; update when seen | G10: Community cessation window (rows 41–42, 44)
A11: 6 | B11: DISTRIBUTION — how well will the rains be spread in time and place? | C11: T | D11: 3 Good (evenly spread), 2 Fair (some dry spells), 1 Poor (erratic, long dry spells), 0 Not sure | E11: Observer, agreed by ITK holders | F11: FGD; update when seen | G11: Distribution counts and weights (rows 47–50)
A12: 7 | B12: AMOUNT — how much rain does the sign point to? | C12: U | D12: 3 above normal, 2 normal, 1 below normal, 0 no prediction yet | E12: Observer, agreed by ITK holders | F12: FGD; update when seen | G12: Tercile tally (rows 11–14)
A13: 8 | B13: How reliable is the sign now? | C13: M | D13: 3 High, 2 Medium, 1 Low, 0 Not sure | E13: FGD/ ITK holders | F13: FGD | G13: Weight (stones) of the sign
A14: 9 | B14: How useful is it for a real decision? | C14: V | D14: 3 High, 2 Medium, 1 Low, 0 Not sure (see Weighting Options tab, section C, for indicative values by role) | E14: FGD | F14: FGD | G14: Weight (stones) of the sign
A15: 10 | B15: Confirmed by an ITK holder, FGD or plenary? | C15: AC | D15: 1 = Yes, 0 = No (names in Observed-by or Notes) | E15: ITK holder/ plenary | F15: FGD; weekly panel | G15: Gate; corroboration
A16: 11 | B16: Approved by a second (lead) ITK holder? | C16: AD | D16: 1 = Yes, 0 = No | E16: Lead ITK holder | F16: Weekly/ fortnightly panel | G16: Gate; corroboration
A17: 12 | B17: How widely is the sign accepted? | C17: AP | D17: FGD-validated only / Community/Plenary-endorsed / Sub-community-specific / Provisional/emerging / Contested (exact dropdown wording) | E17: Plenary | F17: Plenary | G17: Gate: Contested is not counted
A19: B. With every sighting — supports checking and later scoring
A20: # | B20: What to report | C20: Column(s) | D20: How to record it | E20: Who reports/ decides | F20: When | G20: Feeds (Tally tab)
A21: 1 | B21: Where and when it was seen | C21: O | D21: Date and place, e.g. "12/10/2026, Mutirithia dam" | E21: Observer | F21: Each sighting | G21: Evidence
A22: 2 | B22: How reliable was the sign in the past? | C22: L | D22: 3 High, 2 Medium, 1 Low, 0 Not sure | E22: FGD/ ITK holders | F22: FGD | G22: Stability flag
A23: 3 | B23: Where does the sign hold true? | C23: AR | D23: Whole ward, or riverine/ dam, highland/ hills, plains/ grazing areas | E23: FGD | F23: FGD | G23: Geographic scope
A24: 4 | B24: Photos, GPS point and nearby landmark | C24: Y–AA | D24: At least 3 photos (all sides); GPS; landmark | E24: Observer (learners with ICT teacher) | F24: Each sighting | G24: Evidence
A25: 5 | B25: Who observed it | C25: AB | D25: Name or group | E25: Observer | F25: Each sighting | G25: Validation chain
A26: 6 | B26: Consent to share | C26: BC | D26: 1 or 0, then sharing level (1–4) and credit | E26: ITK holder | F26: FGD | G26: Data sovereignty
A28: C. After the season — scoring (changes next season's weights)
A29: # | B29: What to report | C29: Column(s) | D29: How to record it | E29: Who reports/ decides | F29: When | G29: Feeds (Tally tab)
A30: 1 | B30: When did the rains actually START? | C30: AS | D30: Date (dd/mm/yyyy) | E30: Observers, with rain gauge/ school station | F30: At onset | G30: Onset check (Early/ Within/ Late)
A31: 2 | B31: When did the rains actually END? | C31: AT | D31: Date (dd/mm/yyyy) | E31: Observers, with rain gauge/ school station | F31: At cessation | G31: Cessation check
A32: 3 | B32: How well were the rains actually spread? | C32: AU | D32: 3 Good, 2 Fair, 1 Poor | E32: Observers, NDMA monitor, KMSA | F32: End of season | G32: Distribution check
A33: 4 | B33: How much rain did the season actually bring? | C33: AV | D33: 3 above, 2 normal, 1 below | E33: Technical officer with community | F33: End of season | G33: Scoring
A34: 5 | B34: Did this sign's prediction come true? | C34: AZ | D34: Hit, Miss or False Start (using the onset, cessation, distribution and amount checks) | E34: ITK holders with technical officer | F34: January review | G34: Hit rate → next season's weight
A36: D. Not the community's task (data desk, technical officer, automatic)
A37: # | B37: What to report | C37: Column(s) | D37: How to record it | E37: Who reports/ decides | F37: When | G37: Feeds (Tally tab)
A38: 1 | B38: Unique Indicator ID (from the Indicator Code Legend; same ID every season) | C38: AH | D38: e.g. 01-ANI-FRO-001 | E38: School data desk | F38: When entering | G38: Joins seasons; gate
A39: 2 | B39: Site and season, typed exactly as on the Tally tab | C39: AI, AM | D39: e.g. Mutirithia; OND 2026 | E39: School data desk | F39: When entering | G39: Selects rows for the tally
A40: 3 | B40: Verified against gauges and data | C40: AE | D40: 1 = Yes, 0 = No | E40: Extension officer/ NDMA monitor/ CDMS | F40: Weekly check | G40: Validation chain
A41: 4 | B41: Entered by | C41: AF | D41: Name and date | E41: School data desk | F41: Weekly | G41: Accountability
A42: 5 | B42: Weights, checks and tally feed | C42: AW–AY, BL–BT, CA–CH, and v4 auto columns (CJ, CM, CP, CS–CV, DH, DI, DK, DQ–DT) | D42: Calculated — do not type | E42: Spreadsheet | F42: Automatic | G42: All tally figures
A44: Counted in the tally only if: ID present; sighted = 1; confirmed = 1; approved = 1; not Contested; amount 3, 2 or 1. Onset, cessation and distribution are summarised from the same counted signs.
A46: E. Items asked in the FGD but missing from this list in v3, and new v4 items
...

Sheet Sheet 1 - Indicator Log
A1: DEMO COPY WITH HYPOTHETICAL DATA (rows 12–34) — for training on how the Seasonal Tercile Tally is derived. Use the clean Master Template for real data. Table: TILKIT - Traditional Indigenous and Local Knowledge Indicator Tool - for community weather forecast - for FGD and plenary at the community workshops and for community indicator monitoring
A2: A | B2: B | C2: C | D2: D | E2: E | F2: F | G2: G | H2: H | I2: I | J2: J | K2: K | L2: L | M2: M | N2: N | O2: O | P2: P | Q2: Q | R2: R | S2: S | T2: T | U2: U | V2: V | W2: W | X2: X | Y2: Y | Z2: Z | AA2: AA | AB2: AB | AC2: AC | AD2: AD | AE2: AE | AF2: AF | AG2: AG | AH2: AH | AI2: AI | AJ2: AJ | AK2: AK | AL2: AL | AM2: AM | AN2: AN | AO2: AO | AP2: AP | AQ2: AQ | AR2: AR | AS2: AS | AT2: AT | AU2: AU | AV2: AV | AW2: AW | AX2: AX | AY2: AY | AZ2: AZ | BA2: BA | BB2: BB | BC2: BC | BD2: BD | BE2: BE | BF2: BF | BG2: BG | BH2: BH | BI2: BI | BJ2: BJ | BK2: BK | BL2: BL | BM2: BM | BN2: BN | BO2: BO | BP2: BP | BQ2: BQ | BR2: BR | BS2: BS | BT2: BT | BU2: BU | BV2: BV | BW2: BW | BX2: BX | BY2: BY | BZ2: BZ | CA2: CA | CB2: CB | CC2: CC | CD2: CD | CE2: CE | CF2: CF | CG2: CG | CH2: CH | CI2: CI | CJ2: CJ | CK2: CK | CL2: CL | CM2: CM | CN2: CN | CO2: CO | CP2: CP | CQ2: CQ | CR2: CR | CS2: CS | CT2: CT | CU2: CU | CV2: CV | CW2: CW | CX2: CX | CY2: CY | CZ2: CZ | DA2: DA | DB2: DB | DC2: DC | DD2: DD | DE2: DE | DF2: DF | DG2: DG | DH2: DH | DI2: DI | DJ2: DJ | DK2: DK | DL2: DL | DM2: DM | DN2: DN | DO2: DO | DP2: DP | DQ2: DQ | DR2: DR | DS2: DS | DT2: DT
A3: Indicator category (Nature of Indicator) | B3: Indicator type (and sub type) | C3: Specific indicator: e.g., Type = Plants; Sub Type = Tree; Specific Indicator = a specific named tree. Please provide local name of the indicator (always known), English name (if known) and Scientific name (if known) | D3: Indicator behaviour: how does the indicator show itself in a way that predicts the weather? What does the indicator do that makes it predict weather? (e.g., tree flowering intensity, tree leaf blooming, frogs croaking at night) | E3: Indicator prediction in local words: what the community says this behaviour foretells (e.g., 'heavy rains will come within two weeks'; 'the rains will be short this season') | F3: Description of the locality/ landscape where the indicator is applicable (village, hill, river, grazing area). Site, ward, county, country and season/ year are recorded once in AI–AM — do not repeat them here. | G3: Name of the ethnic community that provides the language for the local name of the indicator | H3: Indicator behaviour Interpretation in weather prediction terms: what does the indicator mean in local weather prediction (i.e., what does the indicator behaviour predict in terms of weather events?)(what does the indicator predict (can select more than one) 1: rain start (onset); 2: rain end (cessation); 3: rain distribution e.g., 3a) for long or short duration in the season, or 3b) in many or few places in the locality); 4: rain amount (e.g., more or less rain) | I3: Application of the indicator interpretation in terms of impact-based weather forecasting - how is the predicted weather likely to affect the following livelihoods or sectors in the locality?: - 1: crops/ farming, 2: livestock/ pastoralism, 3: fisheries/ aquaculture, 4: water resources; 5: Forestry/ Environment; 6: Private Sector (trade, business, production); 7: health, 8: education/ school, 9: disaster risk (floods, drought), 10: Public Safety, etc. | J3: Indicator history: is it a historical (ancient) indicator or a new (emerging) one? 3 = ancient/ historical; 2 = recent but promising; 1 = new (emerging); 0 = Not sure. (A sign moving from 3 to 1–2 in elders' accounts, or 'disappearing', is a climate-change signal — see CN–CP.) | K3: Lead time: how long after first observation of the indicator does the predicted weather happen? 3 = months (strategic); 2 = weeks (tactical); 1 = days (operational/ emergency); 0 = Not sure. Exact lead in days is calculated in CU from the dates. | L3: Historical reliability rating of weather prediction accuracy: How reliable was this indicator in this locality in the past)?: 3 High (green) 2 Medium (amber) 1 Low (red) 0 Not sure (grey) | M3: Current reliability rating of weather prediction accuracy (How reliable is this indicator in this locality currently)?: 3 High (green) 2 Medium (amber) 1 Low (red) 0 Not sure (grey) (Used as the Base Weight until the indicator has 3 scored seasons) | N3: Has the indicator been sighted (= observed) this season? 1 = Yes (forecast can now be made); 0 = No (forecast not yet possible). Record where and when in the next column. Only rows coded 1 enter the Seasonal Tercile Tally. | O3: Where and when was it sighted (free text: place/ landmark and date)? Leave blank if N = 0. Type the date again as a date in CI so it can feed the seasonal calendar and lead-time calculations. | P3: In view of, and based on, the information so far available from this weather indicator, by the rating of this locality, respond to the following questions: | Y3: Photos (at least three) - as observed and as appropriate - (e.g., plant leaves, flowers, fruits, or other important features of the indicator as observed, etc.) | Z3: GPS Location | AA3: Landmark feature near GPS location | AB3: Control/ Safeguards/Validation | AG3: Calibration | AH3: Indicator & Data Record Identification (for multi-season, multi-community tracking) | AP3: Validation & Endorsement Status (from FGD and Plenary validation) | AS3: Actual Outcome & Prediction Verification (for Calibration — to be completed after the season) | BB3: Safety, Governance and Evidence | BF3: Reference to the Integrated Consensus Forecast this indicator's rating fed into (Forecast ID/ date, from the knowledge integration session) | BG3: Observer Demographic Profile (for equity monitoring across the dataset) | BL3: Calibration Metrics (auto-calculated from Indicator ID and outcome history — do not edit these cells directly) | BU3: Hazard, Risk, Impact, Opportunity and Linked Actions (traces this indicator forward to the community's risk/impact assessment and separate action-planning documents) | CA3: Weighting Protocol Outputs (auto-calculated per the TILKIT Indicator Weighting Protocol — do not edit directly) | CD3: Data Checks and Tally Feed (auto — do not edit) | CI3: Seasonal Indicator Calendar & Climate-Change Detection (v4) — links each sighting to the seasonal weather indicator calendar and tracks change against elders' memory | CQ3: Vegetation Condition (v4) — community forecast of pasture/ vegetation condition, checked against the NDMA 3-month Vegetation Condition Index (VCI3M) | CU3: Forecast-based Anticipatory Action (v4) — lead time, decision horizon, objectives served and results of early action | DA3: Warning Communication & Dissemination (v4) — did the advisory based on this sign reach people in time, and did they understand and act? | DJ3: Conventional Climate Services, Residual Risk & Messaging (v4) — comparison with KMD/ KMSA and NDMA products | DQ3: Confidence & Priority Weighting (v4, auto — do not edit; weights set on the 'Weighting Options' tab)
P4: Predicted onset — EARLIEST date (dd/mm/yyyy): based on this indicator, when will the rains start at the earliest? Give the window as earliest date here and latest date in the next column (e.g. 20/10/2026 and 31/10/2026). Ask about the coming season (OND) only. | Q4: Predicted onset — LATEST date (dd/mm/yyyy): the end of the window in which this sign says the rains will start. Leave blank if the sign gives a single date. | R4: Predicted cessation — EARLIEST date (dd/mm/yyyy): according to this sign, when will the rains end at the earliest? Blank if the sign says nothing about cessation. | S4: Predicted cessation — LATEST date (dd/mm/yyyy): the end of the window in which this sign says the rains will stop. | T4: Predicted distribution of the rains (how well spread in time and space): 3 Good — evenly spread, few dry spells 2 Fair — some dry spells or uneven areas 1 Poor — erratic, long dry spells or very uneven 0 Not sure/ no prediction | U4: b) On the basis of this particular indicator alone, and on the basis of the information so far available, is the rain for the season likely to be (?): 3) More than average (above normal) 2) Average (Normal) = as usual according to this area 1) Less than average (below normal) 0) No prediction yet (Enter the number only. 0 or blank is not tallied.) | V4: Decision relevance (1–3): How useful is this indicator's prediction for a real decision this season (e.g., in terms of predicting a) when to plant, b) when to move livestock, whether to prepare for c) floods or d) drought)? 3 High (green) — directly guides a decision 2 Medium (amber) — useful supporting signal 1 Low (red) — interesting but rarely acted on 0 Not sure (Multiplies the Final Weight; blank or 0 is treated as 1 and flagged in the Data check column.) | W4: c) Again, On the basis of this particular indicator alone, and on the basis of the information so far available, what plans or actions or strategies can you advise to be adopted in your community based on this current weather prediction available to you? | X4: Sector impact rating of this prediction for each relevant sector, on the traffic-light scale 3 High, 2 Medium, 1 Low, 0 Not sure, with (+) for benefit or (−) for harm, e.g., 'Water 3−; Crops 2+; Livestock 2−; Health 3−; Pastoralism 1+; Infrastructure 3−; Environment 2+; Energy 0; Forestry 1+; Fisheries 0' | AB4: Observed by (any observant member of community): Who has observed the indicator? Name | AC4: Confirmed => a) ITK Holder in the community, or b) FGD/ Plenary participants): Has the observation been confirmed? Code 1 = Yes, 0 = No (dropdown) — put the name(s) in the Notes or Observed-by column, not here, or the tally will not count it. | AD4: Approved (ITK Holder in the community): Has the observation been approved for use? Code 1 = Yes, 0 = No (names elsewhere). Rows need Confirmed = 1 AND Approved = 1 to be tallied. | AE4: Verified (technical expert in the community — to capture hits and misses): Has the confirmation been verified? Code 1 = Yes, 0 = No. Put the expert's name in the Notes column. | AF4: Entered by (school data desk/ rapporteur): name and date the record was keyed into this log | AG4: Analysis of reliability (free text): summarise this indicator's record of hits, misses and false starts and how this should adjust its prediction confidence. The scored outcome itself goes in AZ (word), the rates are calculated in BN–BS. | AH4: Unique Indicator ID — the SAME code for this physical indicator in every season and site, built from the 'Indicator Code Legend' tab (Category-Type-Subtype + running number, e.g., 01-ANI-FRO-001). Do NOT include the season or site in the ID. Required: rows without an ID are not tallied. | AI4: Community/ Site name where this record was collected | AJ4: Lower sub-national level (e.g., Ward/ Location) where this record was collected | AK4: Upper sub-national level (e.g., County/ Region) | AL4: Country | AM4: Season/ Year this record refers to, always in the form 'SSS YYYY' (e.g., OND 2026; MAM 2027; 'July 2026' for monthly checks). Type exactly as on the Tally tab B4. | AN4: Date of data collection (date of the FGD/ Plenary/ interview at which this indicator was recorded — NOT the date the indicator was sighted in the field) | AO4: Language in which the local name and description were originally given | AP4: Validation status (dropdown, choose one): FGD-validated only | Community/Plenary-endorsed | Sub-community-specific (recognised by one livelihood/ demographic group only) | Provisional/emerging (not yet fully established) | Contested (differing accounts — excluded from the tally) | AQ4: If Sub-community-specific or Contested, specify which group or groups 1) recognize the indicator, 2) dispute the indicator, or 3) hold this indicator to be trusted, and briefly why | AR4: Geographic scope of applicability: Is this indicator understood by the community to apply to the whole locality, or only to a specific micro-zone/ area? (specify area if limited) | AS4: Actual (observed) rain onset date this season, once known (dd/mm/yyyy) — from rain gauges, the school weather station, NDMA/ KMSA | AT4: Actual (observed) rain cessation date this season, once known (dd/mm/yyyy) | AU4: Actual (observed) distribution this season, once known: 3 Good, 2 Fair, 1 Poor (from rain gauges, NDMA and KMSA reports) | AV4: Actual (observed) season classification, once known: 3) More/ above normal 2) Normal/ Long term average 1) Less/ below normal | AW4: Onset check (auto): actual onset compared with this sign's predicted window — Early, Within window or Late. Use when deciding Hit/ Miss/ False Start. | AX4: Cessation check (auto): actual cessation compared with this sign's predicted cessation window — Early, Within window or Late. | AY4: Distribution check (auto): predicted vs actual distribution — Matched, Off by one class, or Missed. | AZ4: Outcome after the season — choose the word from the dropdown: Hit (predicted tercile and onset window reasonably matched the actual outcome), Miss (predicted tercile substantially did not match) or False Start (the season began as predicted but the rains failed or were significantly interrupted). Compare P–U with AS–AY. | BA4: Notes on reliability, hits, misses and false starts (if any, per indicator). If the facilitator treats several indicators as one composite vote (Protocol Step 5), record it here and reduce the other members' Decision relevance accordingly. | BB4: Do-no-harm/ safety flag: could acting on this indicator's advice go against an official hazard warning already issued, or any other necessary precaution in the community? 1 = Yes (flag for technical expert review before use in any advisory), 0 = No (can be approved for dissemination). | BC4: Consent/ data-sharing: Has any ITK Holder/ community agreed to this indicator being shared, cited or used beyond this project? Start with 1 = Yes or 0 = No, then give the sharing level (1: community only, 2: project partners, 3: public sharing with credit or attribution (e.g. '1; level 3; credit: Mutirithia ITK holders'.), 4: public sharing anonymous | BD4: Audio/ video recording reference (if available), capturing the ITK Holder's own description of the indicator in their own words | BE4: Cross-reference/ duplicate link: If this indicator was merged with, or duplicates, another logged indicator, note that other Indicator ID here | BG4: Number of observers/ contributors to this indicator entry (count) | BH4: Gender composition of observer(s): 1) All male 2) All female 3) Mixed (male & female) 4) Not recorded/ Prefer not to say | BI4: Age/ generation composition of observer(s): 1) Youth (approx. under 35) 2) Adult 3) Elder 4) Mixed 5) Not recorded/ Prefer not to say | BJ4: Livelihood/ occupation of observer(s): 1) Farmer 2) Pastoralist 3) Trader 4) Fisherfolk 5) Other (specify) 6) Mixed 7) Not recorded/ Prefer not to say | BK4: Does the observer group include (a) person(s) with disability? 1 = Yes, 0 = No, 2 = Not recorded/ prefer not to say | BL4: Cumulative Corroboration Count (number of seasons this Indicator ID has been independently Confirmed AND Approved, across all logged seasons) | BM4: Cumulative Scored Seasons (number of seasons this Indicator ID has a recorded Hit, Miss, or False Start outcome) | BN4: Cumulative Hit Count (this Indicator ID, all seasons) | BO4: Cumulative Miss Count (this Indicator ID, all seasons) | BP4: Cumulative False Start Count (this Indicator ID, all seasons) | BQ4: Hit Rate (cumulative) = Hit Count ÷ Scored Seasons | BR4: Miss Rate (cumulative) = Miss Count ÷ Scored Seasons | BS4: False-Start Rate (cumulative) = False Start Count ÷ Scored Seasons | BT4: Weighting Phase (auto): “Rating-based” if fewer than 3 scored seasons; “Hit-rate-based” once 3 or more — per the TILKIT Indicator Weighting Protocol | BU4: Hazard type implied by this indicator's prediction — type the MAIN hazard number first (used for priority weighting in DR), others after a semicolon: 1) Drought/ dry spell 2) Excess rain/ flood 3) Windstorm 4) Erratic/ unreliable rainfall distribution 5) Heat stress 6) Pest/ disease outbreak risk 7) Other (specify) 8) None/ not applicable | BV4: Risk/ Impact (free text): who or what is exposed and vulnerable to this hazard, and what the anticipated impact would be if it materializes (e.g., on crops, livestock, water access, mobility, safety) | BW4: Opportunity flag: Does this forecast direction also create a potential opportunity (e.g., expanded planting, water storage, favourable market conditions)? Start with 1 = Yes or 0 = No; if 1, briefly describe it, e.g. '1; harvest roof water for the school garden'. | BX4: Community Representatives Action reference (Action ID/ date, linking to the separate Community Representatives Action Plan document — held outside this log — where the full plan built from this indicator is recorded) | BY4: Intermediary Officer Action reference (Action ID/ date, linking to the separate Intermediary Officer Action Plan document — held outside this log — where the full plan built from this indicator is recorded) | BZ4: Integrated Action reference (Action ID/ date, linking to the separate Integrated Action Plan document — held outside this log — where the combined community + technical plan is recorded) | CA4: Base Weight (auto): current reliability rating (Rating-based phase: 3 High, 2 Medium, 1 Low, 0 Not sure) or hit-rate band (Hit-rate-based phase: ≥70% = 3 High, ≥40% = 2 Medium, below 40% = 1 Low), capped at 2 while the indicator has fewer than 2 corroborating records — Protocol Steps 2–4 | CB4: Final Weight (auto) = Base Weight × Decision relevance (blank or 0 relevance counts as 1). Range 0–9. Blank when the current rating is 0/blank in the Rating-based phase. | CC4: Stability Flag (auto): flags a ≥2-point swing between historical (col L) and current (col M) rating for facilitator discussion — Protocol Step 4 | CD4: Duplicate check (auto): flags a second row with the same Unique Indicator ID, Community/ Site and Season/ Year. Keep ONE row per indicator per site per season — update that row rather than adding new ones for later sightings. | CE4: Tally status (auto): whether this row is counted in the Seasonal Tercile Tally for the site and season selected on that tab, and if not, why | CF4: Global prior multiplier (auto, reference): literature-based priority of this indicator type from the 'Prior Multipliers' tab (1.00 = average). Used only if switched on in the Tally tab, and only for Rating-based (unscored) indicators | CG4: Weight used in the tally (auto): Final Weight, multiplied by the global prior only when the Tally tab switch is 'Yes' and the indicator is still Rating-based | CH4: Tally weight as a number (auto helper): weight used in the tally, 0 if none — used for the weighted onset/ cessation averages on the Tally tab | CI4: Date sighted (dd/mm/yyyy) — the same date as in O, typed as a date. Feeds the Seasonal Indicator Calendar, lead time (CU) and calendar shift (CM). | CJ4: Month sighted (auto, 1–12) from CI | CK4: Traditional/ local calendar period when this sign normally appears (local month or season name, e.g., 'Lomuk' or 'end of the cold dry season') | CL4: Expected month in a normal year (1–12, by elders/ ITK holders) — the slot of this sign on the seasonal weather indicator calendar | CM4: Calendar shift (auto, months): sighting month − expected month (−6…+6). Negative = earlier than the calendar, positive = later. ≥1 month either way is a change signal. | CN4: Observed change in this sign compared with elders' memory (dropdown): No change | Appears earlier | Appears later | Less often/ fewer | More often/ more | Disappeared/ rarely seen | Meaning changed | Not sure | CO4: Likely driver of the change, agreed by ITK holders and the technical officer (dropdown): Climate change/ variability | Land-use/ habitat loss | Water development | Pollution/ chemicals | Hunting/ harvesting | Mixed/ several | Unknown | CP4: Climate-change signal flag (auto): counts five signals — calendar shift ≥1 month (CM); stability flag (CC); reported change (CN); reliability decline historical→current (L−M ≥1); hit rate below 40% after ≥3 scored seasons. 2+ signals = STRONG. | CQ4: Predicted vegetation/ pasture condition for the season from this sign: 3 Good (green pasture, browse plentiful), 2 Fair (patchy), 1 Poor (dry, scarce), 0 Not sure | CR4: Actual 3-month VCI (VCI3M, 0–100) for the ward/ sub-county from the NDMA monthly drought early-warning bulletin, at the end of the season | CS4: Actual vegetation class (auto from CR): 3 = VCI3M ≥35 (normal or above-normal greenness), 2 = 20–34 (moderate deficit), 1 = <20 (severe/ extreme deficit) | CT4: Vegetation check (auto): Matched, Off by one class, or Missed | CU4: Lead time available (auto, days) = earliest predicted onset (P) − date sighted (CI) | CV4: Decision horizon (auto) from CU: Strategic (≥60 days), Tactical (7–59), Operational (3–6), Emergency (0–2) — after Osumba et al. (2023) | CW4: Objective(s) the linked early action serves (multi-objective framework; list codes, e.g., '2;3;4'): 1 Lives/ health; 2 Livelihood assets (crops, livestock); 3 Food & nutrition; 4 Water; 5 Education continuity; 6 Environment/ ecosystems; 7 Income/ market opportunity | CX4: Timing of the linked action (dropdown): Anticipatory (before hazard) | At onset | Response (during) | Recovery (after) | CY4: Early action implemented? 1 = Yes, 0 = No | CZ4: Result of the action (after the season): 3 Losses avoided/ reduced, 2 Partly, 1 No effect, 0 Not assessed | DA4: Advisory based on this sign disseminated? 1 = Yes, 0 = No | DB4: Date disseminated (dd/mm/yyyy) | DC4: Channel(s) used (codes, e.g., '1;2;4'): 1 Baraza/ chief; 2 Local-language radio; 3 SMS/ WhatsApp; 4 School/ learners; 5 Church/ mosque; 6 Extension/ NDMA officer; 7 Notice board; 8 Other | DD4: Number of people reached (estimate) | DE4: Of whom women, youth or persons with disability (number) | DF4: Recipients who understood the message (% from feedback/ spot check, 0–100) | DG4: Recipients who acted on the message (% from feedback/ spot check, 0–100) | DH4: Warning lead (auto, days) = earliest predicted onset (P) − date disseminated (DB). Negative = advisory came after the predicted onset. | DI4: Inclusion share (auto) = DE ÷ DD | DJ4: KMD/ KMSA county seasonal outlook tercile for this site and season: 3 Above, 2 Near normal, 1 Below (from the county outlook) | DK4: Agreement with KMD/ KMSA (auto): Agrees, Differs by one class, or Opposite | DL4: NDMA drought early-warning phase for the county/ sub-county in the latest monthly bulletin (dropdown): Normal | Pre-Alert | Alert | Alarm | Emergency | Recovery | DM4: Residual risk: does this sign warn of a hazard, place, timing or group that the KMD/ KMSA outlook or NDMA bulletin does not cover (e.g., micro-zone dry spell, pest, local flash flood, late onset in one valley)? 1 = Yes, 0 = No | DN4: Residual risk — describe what is missed and who is exposed | DO4: Residual risk included in an action plan (Action ID in BX, BY or BZ)? 1 = Yes, 0 = No | DP4: Suggested message for KMD/ KMSA county advisory or NDMA bulletin: the local-language sign + what it means + what to do (e.g., 'Ilkerra frogs at the dam: rains in 2 weeks — prepare seed and desilt pans') | DQ4: Confidence score (auto, 0–100): weighted mix of track record (CA), corroboration (BL), validation breadth (AP), lead time (K), stability (CC), agreement with KMD/ KMSA (DK), observer numbers (BG) and technical verification (AE). Weights on the 'Weighting Options' tab. | DR4: Hazard priority factor (auto) for the main hazard in BU, from the 'Weighting Options' tab (1.00 = neutral) | DS4: Priority-adjusted tally weight (auto) = tally weight (CG) × hazard priority factor (DR). Used only in the priority-adjusted tally on the Tally tab. | DT4: First record for this ID + site + season (auto helper: 1 = first, 0 = later duplicate). Duplicates are excluded from the tally and from the corroboration/ scored-season counts.
A5: 01. Biological/ Ecological (Plant-based) — 01-PLT | B5: Plants/ crops (Tree, Shrub, Grass, Herb, Vine (Climber), Any Other (specify, e.g., fire)
A6: 01. Biological/ Ecological (Animal-based) — 01-ANI | B6: Animals (Insects, Birds, Mammals, Reptiles, Amphibians, Fish, Spiders, Molluscs, Any Other - specify)
A7: 02. Atmospheric/ Physical / Meteorological — 02-ATM | B7: Wind, cloud, air,rain itself, temperature, humidity, thunder, lightning, rainbow, mist/fog, dew, soil/ dust, etc.
A8: 03. Astronomical / Astrological/ Celestial — 03-AST | B8: Sun, moon, stars, planets, sky, etc.
A9: 04. Hydrological / Water-related — 04-HYD | B9: Water bodies (hydrological): waves,water foam, etc.
A10: 05. Traditional Ritual observations/ Divinatory/ Examination of hidden indicators — 05-RIT | B10: e.g., Examination of he-goat intestines, liver, spleen, etc.
A11: 06. Sensory/ Human body physiological responses (Meteorosensitivity - Meteoropathy) - correlate with barometric pressure science — 06-SEN | B11: Human body sensitivity to environmental changes (temperature, humidity, smell, etc.)
A12: 01 | C12: Frogs croaking at night near the dam | L12: 3 | M12: 3 | N12: 1 | U12: 3 | V12: 3 | AC12: 1 | AD12: 1 | AH12: 01-ANI-FRO-001 | AI12: Mutirithia (DEMO) | AJ12: Segera (demo) | AK12: Laikipia (demo) | AL12: Kenya | AM12: OND 2023 | AO12: Maa | AP12: Community/Plenary-endorsed | AV12: 3 | AW12: =IF(OR(AS12="",P12=""),"",IF(AS12<P12,"Early",IF(AS12>IF(Q12="",P12,Q12),"Late","Within window"))) | AX12: =IF(OR(AT12="",R12=""),"",IF(AT12<R12,"Early",IF(AT12>IF(S12="",R12,S12),"Late","Within window"))) | AY12: =IF(OR(AU12="",T12="",T12=0),"",IF(AU12=T12,"Matched",IF(ABS(AU12-T12)=1,"Off by one class","Missed"))) | AZ12: Hit | BA12: Demo history row | BL12: =IF(AH12="","",COUNTIFS($AH$12:$AH$500,AH12,$AC$12:$AC$500,1,$AD$12:$AD$500,1,$DT$12:$DT$500,1)) -> 4 | BM12: =IF(AH12="","",BN12+BO12+BP12) -> 3 | BN12: =IF(AH12="","",COUNTIFS($AH$12:$AH$500,AH12,$AZ$12:$AZ$500,"Hit",$DT$12:$DT$500,1)) -> 2 | BO12: =IF(AH12="","",COUNTIFS($AH$12:$AH$500,AH12,$AZ$12:$AZ$500,"Miss",$DT$12:$DT$500,1)) -> 1 | BP12: =IF(AH12="","",COUNTIFS($AH$12:$AH$500,AH12,$AZ$12:$AZ$500,"False Start",$DT$12:$DT$500,1)) -> 0 | BQ12: =IF(OR(AH12="",BM12="",BM12=0),"",BN12/BM12) -> 0.66666667 | BR12: =IF(OR(AH12="",BM12="",BM12=0),"",BO12/BM12) -> 0.33333333 | BS12: =IF(OR(AH12="",BM12="",BM12=0),"",BP12/BM12) -> 0 | BT12: =IF(AH12="","",IF(BM12>=3,"Hit-rate-based","Rating-based")) -> Hit-rate-based | CA12: =IF(AH12="","",IF(BT12="Hit-rate-based",MIN(IF(BL12<2,2,3),IF(BQ12>=0.7,3,IF(BQ12>=0.4,2,1))),IF(OR(M12="",M12=0),"",MIN(IF(BL12<2,2,3),M12)))) -> 2 | CB12: =IF(OR(AH12="",CA12=""),"",CA12*IF(OR(V12="",V12=0),1,V12)) -> 6 | CC12: =IF(OR(AH12="",L12="",M12="",L12=0,M12=0),"",IF(ABS(L12-M12)>=2,"FLAG: Review — large swing","OK")) -> OK | CD12: =IF(AH12="","",IF(COUNTIFS($AH$12:$AH$500,AH12,$AI$12:$AI$500,AI12,$AM$12:$AM$500,AM12)>1,"DUPLICATE: same ID, site and season",IF(AND(N12=1,U12<>"",U12<>0,OR(V12="",V12=0)),"Check: decision relevance missing","OK"))) -> OK | CE12: =IF(AH12="","",IF(OR(AI12<>'Seasonal Tercile Tally'!$B$3,AM12<>'Seasonal Tercile Tally'!$B$4),"Other site/ season",IF(DT12=0,"Excluded: duplicate (later row)",IF(N12<>1,"Excluded: not sighted",IF(AC12<>1,"Excluded: not confirmed",IF(AD12<>1,"Excluded: not approved",IF(AP12="Contested","Excluded: contested",IF(OR(U12="",U12=0),"Excluded: no tercile",IF(CB12="","Counted (simple tally only — no weight)","Counted"))))))))) -> Other site/ season | CF12: =IF(AH12="","",IFERROR(INDEX('Prior Multipliers'!$C$6:$C$70,MATCH(LEFT(AH12,10),'Prior Multipliers'!$A$6:$A$70,0)),IFERROR(INDEX('Prior Multipliers'!$C$6:$C$70,MATCH(LEFT(AH12,6),'Prior Multipliers'!$A$6:$A$70,0)),IFERROR(INDEX('Prior Multipliers'!$C$6:$C$70,MATCH(LEFT(AH12,2),'Prior Multipliers'!$A$6:$A$70,0)),1)))) -> 1.21 | CG12: =IF(CB12="","",IF(AND('Seasonal Tercile Tally'!$B$5=1,BT12="Rating-based"),CB12*CF12,CB12)) -> 6 | CH12: =IF(ISNUMBER(CG12),CG12,0) -> 6 | CJ12: =IF(CI12="","",MONTH(CI12)) | CM12: =IF(OR(CJ12="",CL12=""),"",MOD(CJ12-CL12+6,12)-6) | CP12: =IF(AH12="","",CHOOSE(MIN(IF(CM12="",0,IF(ABS(CM12)>=1,1,0))+IF(LEFT(CC12,4)="FLAG",1,0)+IF(OR(CN12="",CN12="No change",CN12="Not sure"),0,1)+IF(AND(ISNUMBER(L12),ISNUMBER(M12)),IF(AND(M12>0,L12-M12>=1),1,0),0)+IF(N(BM12)>=3,IF(N(BQ12)<0.4,1,0),0),2)+1,"No change signal","Watch: one change signal","STRONG: possible climate-change impact — review")) -> No change signal | CS12: =IF(CR12="","",IF(CR12>=35,3,IF(CR12>=20,2,1))) | CT12: =IF(OR(CS12="",CQ12="",CQ12=0),"",IF(CQ12=CS12,"Matched",IF(ABS(CQ12-CS12)=1,"Off by one class","Missed"))) | CU12: =IF(OR(CI12="",P12=""),"",IF(P12-CI12<0,"",P12-CI12)) | CV12: =IF(CU12="","",IF(CU12>=60,"Strategic (season)",IF(CU12>=7,"Tactical (1 week–2 months)",IF(CU12>=3,"Operational (3–6 days)","Emergency (0–2 days)")))) | DH12: =IF(OR(DB12="",P12=""),"",P12-DB12) | DI12: =IF(OR(DD12="",DE12=""),"",IF(DD12=0,"",DE12/DD12)) | DK12: =IF(OR(DJ12="",U12="",U12=0),"",IF(U12=DJ12,"Agrees",IF(ABS(U12-DJ12)=1,"Differs by one class","Opposite"))) | DQ12: =IF(AH12="","",IFERROR(ROUND(100*('Weighting Options'!$D$7*IF(ISNUMBER(CA12),CA12/3,0)+'Weighting Options'!$D$8*MIN(N(BL12),3)/3+'Weighting Options'!$D$9*IF(AP12="Community/Plenary-endorsed",1,IF(AP12="FGD-validated only",0.75,IF(AP12="Sub-community-specific",0.5,IF(AP12="Provisional/emerging",0.25,0))))+'Weighting Options'!$D$10*IF(ISNUMBER(K12),K12/3,0)+'Weighting Options'!$D$11*IF(CC12="",0.5,IF(CC12="OK",1,0.25))+'Weighting Options'!$D$12*IF(DK12="",0.5,IF(DK12="Agrees",1,IF(DK12="Opposite",0,0.5)))+'Weighting Options'!$D$13*MIN(N(BG12),3)/3+'Weighting Options'!$D$14*IF(AE12=1,1,0))/SUM('Weighting Options'!$D$7:$D$14),0),"")) -> 62 | DR12: =IF(AH12="","",IFERROR(INDEX('Weighting Options'!$D$20:$D$27,VALUE(LEFT(TRIM(BU12),1))),1)) -> 1 | DS12: =IF(OR(CG12="",DR12=""),"",CG12*DR12) -> 6 | DT12: =IF(AH12="","",IF(COUNTIFS($AH$12:AH12,AH12,$AI$12:AI12,AI12,$AM$12:AM12,AM12)=1,1,0)) -> 1
A13: 01 | C13: Frogs croaking at night near the dam | L13: 3 | M13: 3 | N13: 1 | U13: 3 | V13: 3 | AC13: 1 | AD13: 1 | AH13: 01-ANI-FRO-001 | AI13: Mutirithia (DEMO) | AJ13: Segera (demo) | AK13: Laikipia (demo) | AL13: Kenya | AM13: OND 2024 | AO13: Maa | AP13: Community/Plenary-endorsed | AV13: 3 | AW13: =IF(OR(AS13="",P13=""),"",IF(AS13<P13,"Early",IF(AS13>IF(Q13="",P13,Q13),"Late","Within window"))) | AX13: =IF(OR(AT13="",R13=""),"",IF(AT13<R13,"Early",IF(AT13>IF(S13="",R13,S13),"Late","Within window"))) | AY13: =IF(OR(AU13="",T13="",T13=0),"",IF(AU13=T13,"Matched",IF(ABS(AU13-T13)=1,"Off by one class","Missed"))) | AZ13: Hit | BA13: Demo history row | BL13: =IF(AH13="","",COUNTIFS($AH$12:$AH$500,AH13,$AC$12:$AC$500,1,$AD$12:$AD$500,1,$DT$12:$DT$500,1)) -> 4 | BM13: =IF(AH13="","",BN13+BO13+BP13) -> 3 | BN13: =IF(AH13="","",COUNTIFS($AH$12:$AH$500,AH13,$AZ$12:$AZ$500,"Hit",$DT$12:$DT$500,1)) -> 2 | BO13: =IF(AH13="","",COUNTIFS($AH$12:$AH$500,AH13,$AZ$12:$AZ$500,"Miss",$DT$12:$DT$500,1)) -> 1 | BP13: =IF(AH13="","",COUNTIFS($AH$12:$AH$500,AH13,$AZ$12:$AZ$500,"False Start",$DT$12:$DT$500,1)) -> 0 | BQ13: =IF(OR(AH13="",BM13="",BM13=0),"",BN13/BM13) -> 0.66666667 | BR13: =IF(OR(AH13="",BM13="",BM13=0),"",BO13/BM13) -> 0.33333333 | BS13: =IF(OR(AH13="",BM13="",BM13=0),"",BP13/BM13) -> 0 | BT13: =IF(AH13="","",IF(BM13>=3,"Hit-rate-based","Rating-based")) -> Hit-rate-based | CA13: =IF(AH13="","",IF(BT13="Hit-rate-based",MIN(IF(BL13<2,2,3),IF(BQ13>=0.7,3,IF(BQ13>=0.4,2,1))),IF(OR(M13="",M13=0),"",MIN(IF(BL13<2,2,3),M13)))) -> 2 | CB13: =IF(OR(AH13="",CA13=""),"",CA13*IF(OR(V13="",V13=0),1,V13)) -> 6 | CC13: =IF(OR(AH13="",L13="",M13="",L13=0,M13=0),"",IF(ABS(L13-M13)>=2,"FLAG: Review — large swing","OK")) -> OK | CD13: =IF(AH13="","",IF(COUNTIFS($AH$12:$AH$500,AH13,$AI$12:$AI$500,AI13,$AM$12:$AM$500,AM13)>1,"DUPLICATE: same ID, site and season",IF(AND(N13=1,U13<>"",U13<>0,OR(V13="",V13=0)),"Check: decision relevance missing","OK"))) -> OK | CE13: =IF(AH13="","",IF(OR(AI13<>'Seasonal Tercile Tally'!$B$3,AM13<>'Seasonal Tercile Tally'!$B$4),"Other site/ season",IF(DT13=0,"Excluded: duplicate (later row)",IF(N13<>1,"Excluded: not sighted",IF(AC13<>1,"Excluded: not confirmed",IF(AD13<>1,"Excluded: not approved",IF(AP13="Contested","Excluded: contested",IF(OR(U13="",U13=0),"Excluded: no tercile",IF(CB13="","Counted (simple tally only — no weight)","Counted"))))))))) -> Other site/ season | CF13: =IF(AH13="","",IFERROR(INDEX('Prior Multipliers'!$C$6:$C$70,MATCH(LEFT(AH13,10),'Prior Multipliers'!$A$6:$A$70,0)),IFERROR(INDEX('Prior Multipliers'!$C$6:$C$70,MATCH(LEFT(AH13,6),'Prior Multipliers'!$A$6:$A$70,0)),IFERROR(INDEX('Prior Multipliers'!$C$6:$C$70,MATCH(LEFT(AH13,2),'Prior Multipliers'!$A$6:$A$70,0)),1)))) -> 1.21 | CG13: =IF(CB13="","",IF(AND('Seasonal Tercile Tally'!$B$5=1,BT13="Rating-based"),CB13*CF13,CB13)) -> 6 | CH13: =IF(ISNUMBER(CG13),CG13,0) -> 6 | CJ13: =IF(CI13="","",MONTH(CI13)) | CM13: =IF(OR(CJ13="",CL13=""),"",MOD(CJ13-CL13+6,12)-6) | CP13: =IF(AH13="","",CHOOSE(MIN(IF(CM13="",0,IF(ABS(CM13)>=1,1,0))+IF(LEFT(CC13,4)="FLAG",1,0)+IF(OR(CN13="",CN13="No change",CN13="Not sure"),0,1)+IF(AND(ISNUMBER(L13),ISNUMBER(M13)),IF(AND(M13>0,L13-M13>=1),1,0),0)+IF(N(BM13)>=3,IF(N(BQ13)<0.4,1,0),0),2)+1,"No change signal","Watch: one change signal","STRONG: possible climate-change impact — review")) -> No change signal | CS13: =IF(CR13="","",IF(CR13>=35,3,IF(CR13>=20,2,1))) | CT13: =IF(OR(CS13="",CQ13="",CQ13=0),"",IF(CQ13=CS13,"Matched",IF(ABS(CQ13-CS13)=1,"Off by one class","Missed"))) | CU13: =IF(OR(CI13="",P13=""),"",IF(P13-CI13<0,"",P13-CI13)) | CV13: =IF(CU13="","",IF(CU13>=60,"Strategic (season)",IF(CU13>=7,"Tactical (1 week–2 months)",IF(CU13>=3,"Operational (3–6 days)","Emergency (0–2 days)")))) | DH13: =IF(OR(DB13="",P13=""),"",P13-DB13) | DI13: =IF(OR(DD13="",DE13=""),"",IF(DD13=0,"",DE13/DD13)) | DK13: =IF(OR(DJ13="",U13="",U13=0),"",IF(U13=DJ13,"Agrees",IF(ABS(U13-DJ13)=1,"Differs by one class","Opposite"))) | DQ13: =IF(AH13="","",IFERROR(ROUND(100*('Weighting Options'!$D$7*IF(ISNUMBER(CA13),CA13/3,0)+'Weighting Options'!$D$8*MIN(N(BL13),3)/3+'Weighting Options'!$D$9*IF(AP13="Community/Plenary-endorsed",1,IF(AP13="FGD-validated only",0.75,IF(AP13="Sub-community-specific",0.5,IF(AP13="Provisional/emerging",0.25,0))))+'Weighting Options'!$D$10*IF(ISNUMBER(K13),K13/3,0)+'Weighting Options'!$D$11*IF(CC13="",0.5,IF(CC13="OK",1,0.25))+'Weighting Options'!$D$12*IF(DK13="",0.5,IF(DK13="Agrees",1,IF(DK13="Opposite",0,0.5)))+'Weighting Options'!$D$13*MIN(N(BG13),3)/3+'Weighting Options'!$D$14*IF(AE13=1,1,0))/SUM('Weighting Options'!$D$7:$D$14),0),"")) -> 62 | DR13: =IF(AH13="","",IFERROR(INDEX('Weighting Options'!$D$20:$D$27,VALUE(LEFT(TRIM(BU13),1))),1)) -> 1 | DS13: =IF(OR(CG13="",DR13=""),"",CG13*DR13) -> 6 | DT13: =IF(AH13="","",IF(COUNTIFS($AH$12:AH13,AH13,$AI$12:AI13,AI13,$AM$12:AM13,AM13)=1,1,0)) -> 1
A14: 01 | C14: Frogs croaking at night near the dam | L14: 3 | M14: 3 | N14: 1 | U14: 3 | V14: 3 | AC14: 1 | AD14: 1 | AH14: 01-ANI-FRO-001 | AI14: Mutirithia (DEMO) | AJ14: Segera (demo) | AK14: Laikipia (demo) | AL14: Kenya | AM14: OND 2025 | AO14: Maa | AP14: Community/Plenary-endorsed | AV14: 2 | AW14: =IF(OR(AS14="",P14=""),"",IF(AS14<P14,"Early",IF(AS14>IF(Q14="",P14,Q14),"Late","Within window"))) | AX14: =IF(OR(AT14="",R14=""),"",IF(AT14<R14,"Early",IF(AT14>IF(S14="",R14,S14),"Late","Within window"))) | AY14: =IF(OR(AU14="",T14="",T14=0),"",IF(AU14=T14,"Matched",IF(ABS(AU14-T14)=1,"Off by one class","Missed"))) | AZ14: Miss | BA14: Demo history row | BL14: =IF(AH14="","",COUNTIFS($AH$12:$AH$500,AH14,$AC$12:$AC$500,1,$AD$12:$AD$500,1,$DT$12:$DT$500,1)) -> 4 | BM14: =IF(AH14="","",BN14+BO14+BP14) -> 3 | BN14: =IF(AH14="","",COUNTIFS($AH$12:$AH$500,AH14,$AZ$12:$AZ$500,"Hit",$DT$12:$DT$500,1)) -> 2 | BO14: =IF(AH14="","",COUNTIFS($AH$12:$AH$500,AH14,$AZ$12:$AZ$500,"Miss",$DT$12:$DT$500,1)) -> 1 | BP14: =IF(AH14="","",COUNTIFS($AH$12:$AH$500,AH14,$AZ$12:$AZ$500,"False Start",$DT$12:$DT$500,1)) -> 0 | BQ14: =IF(OR(AH14="",BM14="",BM14=0),"",BN14/BM14) -> 0.66666667 | BR14: =IF(OR(AH14="",BM14="",BM14=0),"",BO14/BM14) -> 0.33333333 | BS14: =IF(OR(AH14="",BM14="",BM14=0),"",BP14/BM14) -> 0 | BT14: =IF(AH14="","",IF(BM14>=3,"Hit-rate-based","Rating-based")) -> Hit-rate-based | CA14: =IF(AH14="","",IF(BT14="Hit-rate-based",MIN(IF(BL14<2,2,3),IF(BQ14>=0.7,3,IF(BQ14>=0.4,2,1))),IF(OR(M14="",M14=0),"",MIN(IF(BL14<2,2,3),M14)))) -> 2 | CB14: =IF(OR(AH14="",CA14=""),"",CA14*IF(OR(V14="",V14=0),1,V14)) -> 6 | CC14: =IF(OR(AH14="",L14="",M14="",L14=0,M14=0),"",IF(ABS(L14-M14)>=2,"FLAG: Review — large swing","OK")) -> OK | CD14: =IF(AH14="","",IF(COUNTIFS($AH$12:$AH$500,AH14,$AI$12:$AI$500,AI14,$AM$12:$AM$500,AM14)>1,"DUPLICATE: same ID, site and season",IF(AND(N14=1,U14<>"",U14<>0,OR(V14="",V14=0)),"Check: decision relevance missing","OK"))) -> OK | CE14: =IF(AH14="","",IF(OR(AI14<>'Seasonal Tercile Tally'!$B$3,AM14<>'Seasonal Tercile Tally'!$B$4),"Other site/ season",IF(DT14=0,"Excluded: duplicate (later row)",IF(N14<>1,"Excluded: not sighted",IF(AC14<>1,"Excluded: not confirmed",IF(AD14<>1,"Excluded: not approved",IF(AP14="Contested","Excluded: contested",IF(OR(U14="",U14=0),"Excluded: no tercile",IF(CB14="","Counted (simple tally only — no weight)","Counted"))))))))) -> Other site/ season | CF14: =IF(AH14="","",IFERROR(INDEX('Prior Multipliers'!$C$6:$C$70,MATCH(LEFT(AH14,10),'Prior Multipliers'!$A$6:$A$70,0)),IFERROR(INDEX('Prior Multipliers'!$C$6:$C$70,MATCH(LEFT(AH14,6),'Prior Multipliers'!$A$6:$A$70,0)),IFERROR(INDEX('Prior Multipliers'!$C$6:$C$70,MATCH(LEFT(AH14,2),'Prior Multipliers'!$A$6:$A$70,0)),1)))) -> 1.21 | CG14: =IF(CB14="","",IF(AND('Seasonal Tercile Tally'!$B$5=1,BT14="Rating-based"),CB14*CF14,CB14)) -> 6 | CH14: =IF(ISNUMBER(CG14),CG14,0) -> 6 | CJ14: =IF(CI14="","",MONTH(CI14)) | CM14: =IF(OR(CJ14="",CL14=""),"",MOD(CJ14-CL14+6,12)-6) | CP14: =IF(AH14="","",CHOOSE(MIN(IF(CM14="",0,IF(ABS(CM14)>=1,1,0))+IF(LEFT(CC14,4)="FLAG",1,0)+IF(OR(CN14="",CN14="No change",CN14="Not sure"),0,1)+IF(AND(ISNUMBER(L14),ISNUMBER(M14)),IF(AND(M14>0,L14-M14>=1),1,0),0)+IF(N(BM14)>=3,IF(N(BQ14)<0.4,1,0),0),2)+1,"No change signal","Watch: one change signal","STRONG: possible climate-change impact — review")) -> No change signal | CS14: =IF(CR14="","",IF(CR14>=35,3,IF(CR14>=20,2,1))) | CT14: =IF(OR(CS14="",CQ14="",CQ14=0),"",IF(CQ14=CS14,"Matched",IF(ABS(CQ14-CS14)=1,"Off by one class","Missed"))) | CU14: =IF(OR(CI14="",P14=""),"",IF(P14-CI14<0,"",P14-CI14)) | CV14: =IF(CU14="","",IF(CU14>=60,"Strategic (season)",IF(CU14>=7,"Tactical (1 week–2 months)",IF(CU14>=3,"Operational (3–6 days)","Emergency (0–2 days)")))) | DH14: =IF(OR(DB14="",P14=""),"",P14-DB14) | DI14: =IF(OR(DD14="",DE14=""),"",IF(DD14=0,"",DE14/DD14)) | DK14: =IF(OR(DJ14="",U14="",U14=0),"",IF(U14=DJ14,"Agrees",IF(ABS(U14-DJ14)=1,"Differs by one class","Opposite"))) | DQ14: =IF(AH14="","",IFERROR(ROUND(100*('Weighting Options'!$D$7*IF(ISNUMBER(CA14),CA14/3,0)+'Weighting Options'!$D$8*MIN(N(BL14),3)/3+'Weighting Options'!$D$9*IF(AP14="Community/Plenary-endorsed",1,IF(AP14="FGD-validated only",0.75,IF(AP14="Sub-community-specific",0.5,IF(AP14="Provisional/emerging",0.25,0))))+'Weighting Options'!$D$10*IF(ISNUMBER(K14),K14/3,0)+'Weighting Options'!$D$11*IF(CC14="",0.5,IF(CC14="OK",1,0.25))+'Weighting Options'!$D$12*IF(DK14="",0.5,IF(DK14="Agrees",1,IF(DK14="Opposite",0,0.5)))+'Weighting Options'!$D$13*MIN(N(BG14),3)/3+'Weighting Options'!$D$14*IF(AE14=1,1,0))/SUM('Weighting Options'!$D$7:$D$14),0),"")) -> 62 | DR14: =IF(AH14="","",IFERROR(INDEX('Weighting Options'!$D$20:$D$27,VALUE(LEFT(TRIM(BU14),1))),1)) -> 1 | DS14: =IF(OR(CG14="",DR14=""),"",CG14*DR14) -> 6 | DT14: =IF(AH14="","",IF(COUNTIFS($AH$12:AH14,AH14,$AI$12:AI14,AI14,$AM$12:AM14,AM14)=1,1,0)) -> 1
A15: 01 | C15: Acacia tortilis flowering heavily | L15: 3 | M15: 3 | N15: 1 | U15: 3 | V15: 3 | AC15: 1 | AD15: 1 | AH15: 01-PLT-FLW-001 | AI15: Mutirithia (DEMO) | AJ15: Segera (demo) | AK15: Laikipia (demo) | AL15: Kenya | AM15: OND 2023 | AO15: Maa | AP15: Community/Plenary-endorsed | AV15: 3 | AW15: =IF(OR(AS15="",P15=""),"",IF(AS15<P15,"Early",IF(AS15>IF(Q15="",P15,Q15),"Late","Within window"))) | AX15: =IF(OR(AT15="",R15=""),"",IF(AT15<R15,"Early",IF(AT15>IF(S15="",R15,S15),"Late","Within window"))) | AY15: =IF(OR(AU15="",T15="",T15=0),"",IF(AU15=T15,"Matched",IF(ABS(AU15-T15)=1,"Off by one class","Missed"))) | AZ15: Hit | BA15: Demo history row | BL15: =IF(AH15="","",COUNTIFS($AH$12:$AH$500,AH15,$AC$12:$AC$500,1,$AD$12:$AD$500,1,$DT$12:$DT$500,1)) -> 4 | BM15: =IF(AH15="","",BN15+BO15+BP15) -> 3 | BN15: =IF(AH15="","",COUNTIFS($AH$12:$AH$500,AH15,$AZ$12:$AZ$500,"Hit",$DT$12:$DT$500,1)) -> 3 | BO15: =IF(AH15="","",COUNTIFS($AH$12:$AH$500,AH15,$AZ$12:$AZ$500,"Miss",$DT$12:$DT$500,1)) -> 0 | BP15: =IF(AH15="","",COUNTIFS($AH$12:$AH$500,AH15,$AZ$12:$AZ$500,"False Start",$DT$12:$DT$500,1)) -> 0 | BQ15: =IF(OR(AH15="",BM15="",BM15=0),"",BN15/BM15) -> 1 | BR15: =IF(OR(AH15="",BM15="",BM15=0),"",BO15/BM15) -> 0 | BS15: =IF(OR(AH15="",BM15="",BM15=0),"",BP15/BM15) -> 0 | BT15: =IF(AH15="","",IF(BM15>=3,"Hit-rate-based","Rating-based")) -> Hit-rate-based | CA15: =IF(AH15="","",IF(BT15="Hit-rate-based",MIN(IF(BL15<2,2,3),IF(BQ15>=0.7,3,IF(BQ15>=0.4,2,1))),IF(OR(M15="",M15=0),"",MIN(IF(BL15<2,2,3),M15)))) -> 3 | CB15: =IF(OR(AH15="",CA15=""),"",CA15*IF(OR(V15="",V15=0),1,V15)) -> 9 | CC15: =IF(OR(AH15="",L15="",M15="",L15=0,M15=0),"",IF(ABS(L15-M15)>=2,"FLAG: Review — large swing","OK")) -> OK | CD15: =IF(AH15="","",IF(COUNTIFS($AH$12:$AH$500,AH15,$AI$12:$AI$500,AI15,$AM$12:$AM$500,AM15)>1,"DUPLICATE: same ID, site and season",IF(AND(N15=1,U15<>"",U15<>0,OR(V15="",V15=0)),"Check: decision relevance missing","OK"))) -> OK | CE15: =IF(AH15="","",IF(OR(AI15<>'Seasonal Tercile Tally'!$B$3,AM15<>'Seasonal Tercile Tally'!$B$4),"Other site/ season",IF(DT15=0,"Excluded: duplicate (later row)",IF(N15<>1,"Excluded: not sighted",IF(AC15<>1,"Excluded: not confirmed",IF(AD15<>1,"Excluded: not approved",IF(AP15="Contested","Excluded: contested",IF(OR(U15="",U15=0),"Excluded: no tercile",IF(CB15="","Counted (simple tally only — no weight)","Counted"))))))))) -> Other site/ season | CF15: =IF(AH15="","",IFERROR(INDEX('Prior Multipliers'!$C$6:$C$70,MATCH(LEFT(AH15,10),'Prior Multipliers'!$A$6:$A$70,0)),IFERROR(INDEX('Prior Multipliers'!$C$6:$C$70,MATCH(LEFT(AH15,6),'Prior Multipliers'!$A$6:$A$70,0)),IFERROR(INDEX('Prior Multipliers'!$C$6:$C$70,MATCH(LEFT(AH15,2),'Prior Multipliers'!$A$6:$A$70,0)),1)))) -> 1.35 | CG15: =IF(CB15="","",IF(AND('Seasonal Tercile Tally'!$B$5=1,BT15="Rating-based"),CB15*CF15,CB15)) -> 9 | CH15: =IF(ISNUMBER(CG15),CG15,0) -> 9 | CJ15: =IF(CI15="","",MONTH(CI15)) | CM15: =IF(OR(CJ15="",CL15=""),"",MOD(CJ15-CL15+6,12)-6) | CP15: =IF(AH15="","",CHOOSE(MIN(IF(CM15="",0,IF(ABS(CM15)>=1,1,0))+IF(LEFT(CC15,4)="FLAG",1,0)+IF(OR(CN15="",CN15="No change",CN15="Not sure"),0,1)+IF(AND(ISNUMBER(L15),ISNUMBER(M15)),IF(AND(M15>0,L15-M15>=1),1,0),0)+IF(N(BM15)>=3,IF(N(BQ15)<0.4,1,0),0),2)+1,"No change signal","Watch: one change signal","STRONG: possible climate-change impact — review")) -> No change signal | CS15: =IF(CR15="","",IF(CR15>=35,3,IF(CR15>=20,2,1))) | CT15: =IF(OR(CS15="",CQ15="",CQ15=0),"",IF(CQ15=CS15,"Matched",IF(ABS(CQ15-CS15)=1,"Off by one class","Missed"))) | CU15: =IF(OR(CI15="",P15=""),"",IF(P15-CI15<0,"",P15-CI15)) | CV15: =IF(CU15="","",IF(CU15>=60,"Strategic (season)",IF(CU15>=7,"Tactical (1 week–2 months)",IF(CU15>=3,"Operational (3–6 days)","Emergency (0–2 days)")))) | DH15: =IF(OR(DB15="",P15=""),"",P15-DB15) | DI15: =IF(OR(DD15="",DE15=""),"",IF(DD15=0,"",DE15/DD15)) | DK15: =IF(OR(DJ15="",U15="",U15=0),"",IF(U15=DJ15,"Agrees",IF(ABS(U15-DJ15)=1,"Differs by one class","Opposite"))) | DQ15: =IF(AH15="","",IFERROR(ROUND(100*('Weighting Options'!$D$7*IF(ISNUMBER(CA15),CA15/3,0)+'Weighting Options'!$D$8*MIN(N(BL15),3)/3+'Weighting Options'!$D$9*IF(AP15="Community/Plenary-endorsed",1,IF(AP15="FGD-validated only",0.75,IF(AP15="Sub-community-specific",0.5,IF(AP15="Provisional/emerging",0.25,0))))+'Weighting Options'!$D$10*IF(ISNUMBER(K15),K15/3,0)+'Weighting Options'!$D$11*IF(CC15="",0.5,IF(CC15="OK",1,0.25))+'Weighting Options'!$D$12*IF(DK15="",0.5,IF(DK15="Agrees",1,IF(DK15="Opposite",0,0.5)))+'Weighting Options'!$D$13*MIN(N(BG15),3)/3+'Weighting Options'!$D$14*IF(AE15=1,1,0))/SUM('Weighting Options'!$D$7:$D$14),0),"")) -> 70 | DR15: =IF(AH15="","",IFERROR(INDEX('Weighting Options'!$D$20:$D$27,VALUE(LEFT(TRIM(BU15),1))),1)) -> 1 | DS15: =IF(OR(CG15="",DR15=""),"",CG15*DR15) -> 9 | DT15: =IF(AH15="","",IF(COUNTIFS($AH$12:AH15,AH15,$AI$12:AI15,AI15,$AM$12:AM15,AM15)=1,1,0)) -> 1
